Workbook

Sheet Sheet1
A1: Numeric ID | B1: Cycle | C1: Frame | D1: Time (moment) | E1: MR area cm2 | F1: MR VC mm | G1: LA area cm2 | H1: LA length cm | I1: MV tenting height mm | J1: MV annulus mm | K1: LV area cm2 | L1: LV length cm | M1: RR interval msec
A2: 1 | B2: 1 | C2: 1 | D2: 1 | E2: 0.6 | F2: 2.8 | G2: 15.7 | I2: 3.8 | J2: 31.2 | K2: 46.5 | M2: 898
A3: 1 | B3: 1 | C3: 2 | D3: 2 | E3: 2.3 | F3: 3.9 | G3: 18 | I3: 5.1 | J3: 30.4 | K3: 43.5 | M3: 898
A4: 1 | B4: 1 | C4: 3 | D4: 3 | E4: 1.7 | F4: 2.7 | G4: 20.5 | I4: 4.3 | J4: 35.1 | K4: 41.6 | M4: 898
A5: 1 | B5: 1 | C5: 4 | D5: 4 | E5: 2.5 | F5: 3.8 | G5: 21.8 | I5: 3 | J5: 32.2 | K5: 39.4 | M5: 898
A6: 1 | B6: 1 | C6: 5 | D6: 5 | E6: 2.6 | F6: 2.8 | G6: 23 | I6: 3.5 | J6: 34 | K6: 41.2 | M6: 898
A7: 1 | B7: 2 | C7: 1 | D7: 6 | E7: 7.5 | F7: 2.6 | G7: 17.3 | I7: 16.6 | J7: 31.1 | K7: 46.7 | M7: 878
A8: 1 | B8: 2 | C8: 2 | D8: 7 | E8: 2.6 | F8: 2.2 | G8: 16.5 | I8: 5.2 | J8: 33 | K8: 46.3 | M8: 878
A9: 1 | B9: 2 | C9: 3 | D9: 8 | E9: 0.5 | F9: 3 | G9: 17.2 | I9: 5.5 | J9: 29.9 | K9: 44.9 | M9: 878
A10: 1 | B10: 2 | C10: 4 | D10: 9 | E10: 1.4 | F10: 2.8 | G10: 18.6 | I10: 4.8 | J10: 28.2 | K10: 41 | M10: 878
A11: 1 | B11: 2 | C11: 5 | D11: 10 | E11: 1.1 | F11: 2.6 | G11: 21.4 | I11: 4.4 | J11: 29.1 | K11: 40.5 | M11: 878
A12: 1 | B12: 2 | C12: 6 | D12: 11 | E12: 1.8 | F12: 2.3 | G12: 21.8 | I12: 4.4 | J12: 27.8 | K12: 41.3 | M12: 878
A13: 1 | B13: 3 | C13: 1 | D13: 12 | E13: 4.3 | F13: 3.5 | G13: 15.6 | I13: 22.6 | J13: 28 | K13: 46.3 | M13: 898
... A74: 4 | B74: 1 | C74: 1 | D74: 1 | E74: 2.46 | F74: 3.1 | G74: 22.5 | I74: 4.2 | J74: 35.2 | K74: 20.83 | M74: 689
A75: 4 | B75: 2 | C75: 1 | D75: 2 | E75: 2.6 | F75: 2.2 | G75: 20.3 | J75: 32.2 | K75: 18.2 | M75: 820
A76: 4 | B76: 2 | C76: 2 | D76: 3 | E76: 2.5 | F76: 3.1 | G76: 20.9 | J76: 34.9 | K76: 17.4 | M76: 820
A77: 4 | B77: 2 | C77: 3 | D77: 4 | E77: 1.2 | F77: 2.9 | G77: 20.1 | J77: 33.4 | K77: 16.1 | M77: 820
A78: 4 | B78: 2 | C78: 4 | D78: 5 | E78: 0.7 | F78: 1.4 | G78: 22.8 | J78: 32.2 | K78: 13.4 | M78: 820
A79: 4 | B79: 3 | C79: 1 | D79: 6 | E79: 3.25 | F79: 3.4 | G79: 23.1 | I79: 4.2 | J79: 35.3 | K79: 24.5 | M79: 712
A80: 4 | B80: 4 | C80: 1 | D80: 7 | E80: 3.29 | F80: 2.6 | G80: 23.23 | I80: 4 | J80: 36.6 | K80: 24.1 | M80: 775
A81: 4 | B81: 5 | C81: 1 | D81: 8 | E81: 2.6 | F81: 3.5 | G81: 24 | I81: 3.9 | J81: 35.5 | K81: 20.7 | M81: 721
A82: 4 | B82: 6 | C82: 1 | D82: 9 | E82: 3.32 | F82: 3.2 | G82: 23.7 | I82: 3.3 | J82: 34.2 | K82: 23.2 | M82: 939
A83: 4 | B83: 7 | C83: 1 | D83: 10 | E83: 3.58 | F83: 3.9 | G83: 23.5 | I83: 3.8 | J83: 34.6 | K83: 25.9 | M83: 915
A84: 4 | B84: 8 | C84: 1 | D84: 11 | E84: 3.74 | F84: 2.6 | G84: 23.4 | I84: 3.4 | J84: 35 | K84: 23.2 | M84: 948
A85: 4 | B85: 9 | C85: 1 | D85: 12 | E85: 3.56 | F85: 2.5 | G85: 23.6 | I85: 4.4 | J85: 33.2 | K85: 21.9 | M85: 867
A86: 4 | B86: 10 | C86: 1 | D86: 13 | E86: 3.43 | F86: 2.9 | G86: 24.3 | I86: 4.1 | J86: 33.6 | K86: 20.5 | M86: 599
A87: 5 | B87: 1 | C87: 1 | D87: 1 | E87: 1.3 | F87: 2 | G87: 24 | I87: 9.3 | J87: 38.7 | K87: 29.9 | M87: 956
A88: 5 | B88: 2 | C88: 1 | D88: 2 | E88: 0.3 | F88: 1.6 | G88: 21.2 | J88: 35.5 | K88: 29.7 | M88: 938
A89: 5 | B89: 2 | C89: 2 | D89: 3 | E89: 0.5 | F89: 1.8 | G89: 22.5 | J89: 39.1 | K89: 31.6 | M89: 938
A90: 5 | B90: 2 | C90: 3 | D90: 4 | E90: 0.8 | F90: 2.1 | G90: 23.5 | J90: 36.2 | K90: 28.3 | M90: 938
A91: 5 | B91: 2 | C91: 4 | D91: 5 | E91: 1.5 | F91: 2.4 | G91: 24.7 | J91: 33.1 | K91: 24.4 | M91: 938
A92: 5 | B92: 2 | C92: 5 | D92: 6 | E92: 1.2 | F92: 2.5 | G92: 26.6 | J92: 32 | K92: 21 | M92: 938
A93: 5 | B93: 2 | C93: 6 | D93: 7 | E93: 5.5 | F93: 4.5 | G93: 28.5 | J93: 34.9 | K93: 23.2 | M93: 938
A94: 5 | B94: 3 | C94: 1 | D94: 8 | E94: 1.5 | F94: 2.6 | G94: 22 | I94: 9 | J94: 31.1 | K94: 28.5 | M94: 952
A95: 5 | B95: 4 | C95: 1 | D95: 9 | E95: 1.2 | F95: 2.5 | G95: 23.4 | I95: 7.4 | J95: 29.7 | K95: 29.5 | M95: 938
A96: 4 | B96: 1 | C96: 1 | D96: 1 | E96: 6.9 | F96: 3.93 | G96: 27.8 | I96: 6.1 | J96: 37.6 | K96: 25.7 | M96: 457
A97: 4 | B97: 2 | C97: 1 | D97: 8 | E97: 0.8 | F97: 2.3 | G97: 24.5 | J97: 36.2 | K97: 26.7 | M97: 505
A98: 4 | B98: 2 | C98: 2 | D98: 9 | E98: 5.3 | F98: 3 | G98: 23.5 | J98: 36.5 | K98: 26.8 | M98: 505
A99: 4 | B99: 2 | C99: 3 | D99: 10 | E99: 3.8 | F99: 3.5 | G99: 24.8 | J99: 37.1 | K99: 25.9 | M99: 505
A100: 4 | B100: 2 | C100: 4 | D100: 11 | E100: 5.7 | F100: 3.9 | G100: 24.5 | J100: 36.8 | K100: 23.6 | M100: 505
...

Sheet Sheet2
A1: Numeric ID | B1: Cycle | C1: Frame | D1: Time (moment) | E1: MR area cm2 | F1: MR VC mm | G1: LA area cm2 | I1: MV tenting height mm | J1: MV annulus mm | K1: LV area cm2 | M1: RR interval msec
A2: =Sheet1!A2 -> 1 | B2: =Sheet1!B2 -> 1 | E2: =AVERAGE(Sheet1!E2:E6) -> 1.94 | F2: =AVERAGE(Sheet1!F2:F6) -> 3.2 | G2: =AVERAGE(Sheet1!G2:G6) -> 19.8 | I2: =AVERAGE(Sheet1!I2:I6) -> 3.94 | J2: =AVERAGE(Sheet1!J2:J6) -> 32.58 | K2: =AVERAGE(Sheet1!K2:K6) -> 42.44 | M2: =AVERAGE(Sheet1!M2:M6) -> 898
A3: =Sheet1!A3 -> 1 | B3: 2 | E3: =AVERAGE(Sheet1!E7:E12) -> 2.4833333 | F3: =AVERAGE(Sheet1!F7:F12) -> 2.5833333 | G3: =AVERAGE(Sheet1!G7:G12) -> 18.8 | I3: =AVERAGE(Sheet1!I7:I12) -> 6.8166667 | J3: =AVERAGE(Sheet1!J7:J12) -> 29.85 | K3: =AVERAGE(Sheet1!K7:K12) -> 43.45 | M3: =AVERAGE(Sheet1!M7:M12) -> 878
A4: =Sheet1!A4 -> 1 | B4: 3 | E4: =AVERAGE(Sheet1!E13:E18) -> 1.8 | F4: =AVERAGE(Sheet1!F13:F18) -> 2.5333333 | G4: =AVERAGE(Sheet1!G13:G18) -> 17.783333 | I4: =AVERAGE(Sheet1!I13:I18) -> 7.95 | J4: =AVERAGE(Sheet1!J13:J18) -> 30.616667 | K4: =AVERAGE(Sheet1!K13:K18) -> 42.416667 | M4: =AVERAGE(Sheet1!M13:M18) -> 898
A5: =Sheet1!A5 -> 1 | B5: 4 | E5: =AVERAGE(Sheet1!E19:E23) -> 1.4 | F5: =AVERAGE(Sheet1!F19:F23) -> 2.28 | G5: =AVERAGE(Sheet1!G19:G23) -> 17.72 | I5: =AVERAGE(Sheet1!I19:I23) -> 4.42 | J5: =AVERAGE(Sheet1!J19:J23) -> 29.4 | K5: =AVERAGE(Sheet1!K19:K23) -> 41.94 | M5: =AVERAGE(Sheet1!M19:M23) -> 869
A6: =Sheet1!A6 -> 1 | B6: 5 | E6: =AVERAGE(Sheet1!E24:E27) -> 1.725 | F6: =AVERAGE(Sheet1!F24:F27) -> 2.875 | G6: =AVERAGE(Sheet1!G24:G27) -> 17.525 | I6: =AVERAGE(Sheet1!I24:I27) -> 4.65 | J6: =AVERAGE(Sheet1!J24:J27) -> 32 | K6: =AVERAGE(Sheet1!K24:K27) -> 41.7 | M6: =AVERAGE(Sheet1!M24:M27) -> 827
A7: =Sheet1!A7 -> 1 | B7: 6 | E7: =AVERAGE(Sheet1!E28:E31) -> 1.425 | F7: =AVERAGE(Sheet1!F28:F31) -> 2.575 | G7: =AVERAGE(Sheet1!G28:G31) -> 18.05 | I7: =AVERAGE(Sheet1!I28:I31) -> 4.25 | J7: =AVERAGE(Sheet1!J28:J31) -> 33.275 | K7: =AVERAGE(Sheet1!K28:K31) -> 41.225 | M7: =AVERAGE(Sheet1!M28:M31) -> 827
A8: =Sheet1!A8 -> 1 | B8: 7 | E8: =AVERAGE(Sheet1!E32:E37) -> 2.35 | F8: =AVERAGE(Sheet1!F32:F37) -> 2.2333333 | G8: =AVERAGE(Sheet1!G32:G37) -> 15.75 | I8: =AVERAGE(Sheet1!I32:I37) -> 6.2833333 | J8: =AVERAGE(Sheet1!J32:J37) -> 29.9 | K8: =AVERAGE(Sheet1!K32:K37) -> 42.716667 | M8: =AVERAGE(Sheet1!M32:M37) -> 827
A9: =Sheet1!A9 -> 1 | B9: 8 | E9: =AVERAGE(Sheet1!E38:E43) -> 1.8166667 | F9: =AVERAGE(Sheet1!F38:F43) -> 2.4166667 | G9: =AVERAGE(Sheet1!G38:G43) -> 15.783333 | I9: =AVERAGE(Sheet1!I38:I43) -> 5.4833333 | J9: =AVERAGE(Sheet1!J38:J43) -> 29.85 | K9: =AVERAGE(Sheet1!K38:K43) -> 43.016667 | M9: =AVERAGE(Sheet1!M38:M43) -> 827
A10: =Sheet1!A10 -> 1 | B10: 9 | E10: =AVERAGE(Sheet1!E44:E47) -> 1.5 | F10: =AVERAGE(Sheet1!F44:F47) -> 2.225 | G10: =AVERAGE(Sheet1!G44:G47) -> 17.125 | I10: =AVERAGE(Sheet1!I44:I47) -> 3.825 | J10: =AVERAGE(Sheet1!J44:J47) -> 30.6 | K10: =AVERAGE(Sheet1!K44:K47) -> 42.1 | M10: =AVERAGE(Sheet1!M44:M47) -> 803
A11: =Sheet1!A11 -> 1 | B11: 10 | E11: =AVERAGE(Sheet1!E48:E53) -> 2.5 | F11: =AVERAGE(Sheet1!F48:F53) -> 2.1333333 | G11: =AVERAGE(Sheet1!G48:G53) -> 18.9 | I11: =AVERAGE(Sheet1!I48:I53) -> 7.2666667 | J11: =AVERAGE(Sheet1!J48:J53) -> 31.383333 | K11: =AVERAGE(Sheet1!K48:K53) -> 43.333333 | M11: =AVERAGE(Sheet1!M48:M53) -> 783
A12: 2 | B12: =Sheet1!B54 -> 1 | E12: =Sheet1!E54 -> 9.4 | F12: =Sheet1!F54 -> 4 | G12: =Sheet1!G54 -> 21.5 | I12: =Sheet1!I54 -> 15 | J12: =Sheet1!J54 -> 32 | K12: =Sheet1!K54 -> 71.2 | M12: =Sheet1!M54 -> 902
A13: 2 | B13: =Sheet1!B55 -> 2 | E13: =Sheet1!E55 -> 12 | F13: =Sheet1!F55 -> 9 | G13: =Sheet1!G55 -> 20.9 | I13: =Sheet1!I55 -> 17 | J13: =Sheet1!J55 -> 32 | K13: =Sheet1!K55 -> 69.4 | M13: =Sheet1!M55 -> 898
A14: 2 | B14: =Sheet1!B56 -> 3 | E14: =Sheet1!E56 -> 13.7 | F14: =Sheet1!F56 -> 8 | G14: =Sheet1!G56 -> 20.5 | I14: =Sheet1!I56 -> 15 | J14: =Sheet1!J56 -> 32 | K14: =Sheet1!K56 -> 75.4 | M14: =Sheet1!M56 -> 910
A15: 2 | B15: =Sheet1!B57 -> 4 | E15: =Sheet1!E57 -> 13.5 | F15: =Sheet1!F57 -> 6 | G15: =Sheet1!G57 -> 19.8 | I15: =Sheet1!I57 -> 17 | J15: =Sheet1!J57 -> 34 | K15: =Sheet1!K57 -> 61.8 | M15: =Sheet1!M57 -> 891
A16: 2 | B16: =Sheet1!B58 -> 5 | E16: =Sheet1!E58 -> 11.3 | F16: =Sheet1!F58 -> 8 | G16: =Sheet1!G58 -> 21.6 | I16: =Sheet1!I58 -> 17 | J16: =Sheet1!J58 -> 34 | K16: =Sheet1!K58 -> 69.6 | M16: =Sheet1!M58 -> 754
A17: 2 | B17: =Sheet1!B59 -> 6 | E17: =Sheet1!E59 -> 15.4 | F17: =Sheet1!F59 -> 6 | G17: =Sheet1!G59 -> 27.2 | I17: =Sheet1!I59 -> 15 | J17: =Sheet1!J59 -> 38 | K17: =Sheet1!K59 -> 69.9 | M17: =Sheet1!M59 -> 1028
A18: 2 | B18: =Sheet1!B60 -> 7 | E18: =Sheet1!E60 -> 7.1 | F18: =Sheet1!F60 -> 5 | G18: =Sheet1!G60 -> 18.8 | I18: =Sheet1!I60 -> 18 | J18: =Sheet1!J60 -> 33 | K18: =Sheet1!K60 -> 70.4 | M18: =Sheet1!M60 -> 891
A19: 2 | B19: =Sheet1!B61 -> 8 | E19: =Sheet1!E61 -> 9.9 | F19: =Sheet1!F61 -> 7 | G19: =Sheet1!G61 -> 21.1 | I19: =Sheet1!I61 -> 23 | J19: =Sheet1!J61 -> 35 | K19: =Sheet1!K61 -> 71.2 | M19: =Sheet1!M61 -> 887
A20: 2 | B20: =Sheet1!B62 -> 9 | E20: =Sheet1!E62 -> 12.9 | F20: =Sheet1!F62 -> 6 | G20: =Sheet1!G62 -> 21.2 | I20: =Sheet1!I62 -> 19 | J20: =Sheet1!J62 -> 34 | K20: =Sheet1!K62 -> 72 | M20: =Sheet1!M62 -> 891
A21: 2 | B21: =Sheet1!B63 -> 10 | E21: =Sheet1!E63 -> 11 | F21: =Sheet1!F63 -> 6 | G21: =Sheet1!G63 -> 21.4 | I21: =Sheet1!I63 -> 21 | J21: =Sheet1!J63 -> 35 | K21: =Sheet1!K63 -> 70 | M21: =Sheet1!M63 -> 894
A22: 3 | B22: =Sheet1!B64 -> 1 | E22: =Sheet1!E64 -> 1.7 | F22: =Sheet1!F64 -> 2 | G22: =Sheet1!G64 -> 11.6 | I22: =Sheet1!I64 -> 7 | J22: =Sheet1!J64 -> 32 | K22: =Sheet1!K64 -> 37.3 | M22: =Sheet1!M64 -> 1047
A23: 3 | B23: =Sheet1!B65 -> 2 | E23: =Sheet1!E65 -> 3.1 | F23: =Sheet1!F65 -> 2 | G23: =Sheet1!G65 -> 11.8 | I23: =Sheet1!I65 -> 6 | J23: =Sheet1!J65 -> 33 | K23: =Sheet1!K65 -> 36.8 | M23: =Sheet1!M65 -> 1054
... A32: 4 | B32: =Sheet1!B74 -> 1 | E32: =Sheet1!E74 -> 2.46 | F32: =Sheet1!F74 -> 3.1 | G32: =Sheet1!G74 -> 22.5 | I32: =Sheet1!I74 -> 4.2 | J32: =Sheet1!J74 -> 35.2 | K32: =Sheet1!K74 -> 20.83 | M32: =Sheet1!M74 -> 689
A33: 4 | B33: =Sheet1!B75 -> 2 | E33: =AVERAGE(Sheet1!E75:E78) -> 1.75 | F33: =AVERAGE(Sheet1!F75:F78) -> 2.4 | G33: =AVERAGE(Sheet1!G75:G78) -> 21.025 | I33: =AVERAGE(Sheet1!I75:I78) -> #DIV/0! | J33: =AVERAGE(Sheet1!J75:J78) -> 33.175 | K33: =AVERAGE(Sheet1!K75:K78) -> 16.275 | M33: =AVERAGE(Sheet1!M75:M78) -> 820
A34: 4 | B34: =Sheet1!B79 -> 3 | E34: =Sheet1!E79 -> 3.25 | F34: =Sheet1!F79 -> 3.4 | G34: =Sheet1!G79 -> 23.1 | I34: =Sheet1!I79 -> 4.2 | J34: =Sheet1!J79 -> 35.3 | K34: =Sheet1!K79 -> 24.5 | M34: =Sheet1!M79 -> 712
A35: 4 | B35: =Sheet1!B80 -> 4 | E35: =Sheet1!E80 -> 3.29 | F35: =Sheet1!F80 -> 2.6 | G35: =Sheet1!G80 -> 23.23 | I35: =Sheet1!I80 -> 4 | J35: =Sheet1!J80 -> 36.6 | K35: =Sheet1!K80 -> 24.1 | M35: =Sheet1!M80 -> 775
A36: 4 | B36: =Sheet1!B81 -> 5 | E36: =Sheet1!E81 -> 2.6 | F36: =Sheet1!F81 -> 3.5 | G36: =Sheet1!G81 -> 24 | I36: =Sheet1!I81 -> 3.9 | J36: =Sheet1!J81 -> 35.5 | K36: =Sheet1!K81 -> 20.7 | M36: =Sheet1!M81 -> 721
A37: 4 | B37: =Sheet1!B82 -> 6 | E37: =Sheet1!E82 -> 3.32 | F37: =Sheet1!F82 -> 3.2 | G37: =Sheet1!G82 -> 23.7 | I37: =Sheet1!I82 -> 3.3 | J37: =Sheet1!J82 -> 34.2 | K37: =Sheet1!K82 -> 23.2 | M37: =Sheet1!M82 -> 939
A38: 4 | B38: =Sheet1!B83 -> 7 | E38: =Sheet1!E83 -> 3.58 | F38: =Sheet1!F83 -> 3.9 | G38: =Sheet1!G83 -> 23.5 | I38: =Sheet1!I83 -> 3.8 | J38: =Sheet1!J83 -> 34.6 | K38: =Sheet1!K83 -> 25.9 | M38: =Sheet1!M83 -> 915
A39: 4 | B39: =Sheet1!B84 -> 8 | E39: =Sheet1!E84 -> 3.74 | F39: =Sheet1!F84 -> 2.6 | G39: =Sheet1!G84 -> 23.4 | I39: =Sheet1!I84 -> 3.4 | J39: =Sheet1!J84 -> 35 | K39: =Sheet1!K84 -> 23.2 | M39: =Sheet1!M84 -> 948
A40: 4 | B40: =Sheet1!B85 -> 9 | E40: =Sheet1!E85 -> 3.56 | F40: =Sheet1!F85 -> 2.5 | G40: =Sheet1!G85 -> 23.6 | I40: =Sheet1!I85 -> 4.4 | J40: =Sheet1!J85 -> 33.2 | K40: =Sheet1!K85 -> 21.9 | M40: =Sheet1!M85 -> 867
A41: 4 | B41: =Sheet1!B86 -> 10 | E41: =Sheet1!E86 -> 3.43 | F41: =Sheet1!F86 -> 2.9 | G41: =Sheet1!G86 -> 24.3 | I41: =Sheet1!I86 -> 4.1 | J41: =Sheet1!J86 -> 33.6 | K41: =Sheet1!K86 -> 20.5 | M41: =Sheet1!M86 -> 599
A42: 5 | B42: =Sheet1!B87 -> 1 | E42: =Sheet1!E87 -> 1.3 | F42: =Sheet1!F87 -> 2 | G42: =Sheet1!G87 -> 24 | I42: =Sheet1!I87 -> 9.3 | J42: =Sheet1!J87 -> 38.7 | K42: =Sheet1!K87 -> 29.9 | M42: =Sheet1!M87 -> 956
A43: 5 | B43: =Sheet1!B88 -> 2 | E43: =AVERAGE(Sheet1!E88:E93) -> 1.6333333 | F43: =AVERAGE(Sheet1!F88:F93) -> 2.4833333 | G43: =AVERAGE(Sheet1!G88:G93) -> 24.5 | I43: =AVERAGE(Sheet1!I88:I93) -> #DIV/0! | J43: =AVERAGE(Sheet1!J88:J93) -> 35.133333 | K43: =AVERAGE(Sheet1!K88:K93) -> 26.366667 | M43: =AVERAGE(Sheet1!M88:M93) -> 938
A44: 5 | B44: =Sheet1!B102 -> 3 | E44: =Sheet1!E94 -> 1.5 | F44: =Sheet1!F94 -> 2.6 | G44: =Sheet1!G94 -> 22 | I44: =Sheet1!I94 -> 9 | J44: =Sheet1!J94 -> 31.1 | K44: =Sheet1!K94 -> 28.5 | M44: =Sheet1!M94 -> 952
A45: 5 | B45: =Sheet1!B103 -> 4 | E45: =Sheet1!E95 -> 1.2 | F45: =Sheet1!F95 -> 2.5 | G45: =Sheet1!G95 -> 23.4 | I45: =Sheet1!I95 -> 7.4 | J45: =Sheet1!J95 -> 29.7 | K45: =Sheet1!K95 -> 29.5 | M45: =Sheet1!M95 -> 938
A46: 6 | B46: =Sheet1!B104 -> 5 | E46: =AVERAGE(Sheet1!E96) -> 6.9 | F46: =AVERAGE(Sheet1!F96) -> 3.93 | G46: =AVERAGE(Sheet1!G96) -> 27.8 | I46: =AVERAGE(Sheet1!I96) -> 6.1 | J46: =AVERAGE(Sheet1!J96) -> 37.6 | K46: =AVERAGE(Sheet1!K96) -> 25.7 | M46: =AVERAGE(Sheet1!M96) -> 457
A47: 6 | B47: =Sheet1!B105 -> 6 | E47: =AVERAGE(Sheet1!E97:E101) -> 4.32 | F47: =AVERAGE(Sheet1!F97:F101) -> 3.34 | G47: =AVERAGE(Sheet1!G97:G101) -> 24.4 | I47: =AVERAGE(Sheet1!I97:I101) -> #DIV/0! | J47: =AVERAGE(Sheet1!J97:J101) -> 36.64 | K47: =AVERAGE(Sheet1!K97:K101) -> 25.16 | M47: =AVERAGE(Sheet1!M97:M101) -> 505
A48: 6 | B48: =Sheet1!B106 -> 7 | E48: =Sheet1!E102 -> 1.6 | F48: =Sheet1!F102 -> 2.2 | G48: =Sheet1!G102 -> 24.6 | I48: =Sheet1!I102 -> 5.2 | J48: =Sheet1!J102 -> 32 | K48: =Sheet1!K102 -> 25.1 | M48: =Sheet1!M102 -> 422
...
